<robot name = "pillar30">
	<!-- links section -->>
 <link name = "base">
		<visual>
			<origin xyz = "0 0 0" />
			<geometry>
				<cylinder radius = "0" length = "0"  />
			</geometry>
			<material name = "gray C">
				<color rgba = "0.5 0.5 0.5 1" />
			</material>
		</visual>
	</link>

 <link name = "pillar">
		<visual>
			<origin xyz = "0 0 -0.135" />
			<geometry>
				<mesh filename="./pillar30.STL" />
			</geometry>
			<material name = "gray C">
				<color rgba = "0.5 0.5 0.0 1" />
			</material>  
		</visual>
	</link>
	
<!-- joints section -->>
	<joint name = "joint1" type = "continuous">
		<parent link = "base" />
		<child link = "pillar" />
		<origin xyz = "0 0 0" />
		<axis xyz = "0 0 1" />
	</joint>

</robot>

